# PyTorch Lightning 重复日志错误彻底分析

## 错误信息
```
lightning.fabric.utilities.exceptions.MisconfigurationException: 
You called `self.log(val/focal_loss, ...)` twice in `validation_step` with different arguments. This is not allowed
```

## 问题源头分析

### 1. **直接原因 - 相同键的多次记录**

根据错误堆栈，问题发生在 `model.py` 的第1600行附近的 `self.log_dict()` 调用中。这表明 `val/focal_loss` 这个键被记录了两次，且使用了不同的参数。

### 2. **可能的代码模式问题**

#### 模式A: 混合使用 `self.log` 和 `self.log_dict`
```python
# 问题代码示例
def validation_step(self, batch, batch_idx):
    # ... 模型计算 ...
    
    # 第一次记录 - 单独记录
    self.log("val/focal_loss", focal_loss, prog_bar=True)
    
    # 第二次记录 - 在字典中记录 (不同参数!)
    metrics = {
        "val/focal_loss": focal_loss,  # 重复的键!
        "val/acc": accuracy
    }
    self.log_dict(metrics, sync_dist=True)  # 不同的参数设置
```

#### 模式B: 多个 `log_dict` 调用包含相同键
```python
# 问题代码示例
def validation_step(self, batch, batch_idx):
    # 第一个字典
    loss_metrics = {
        "val/focal_loss": focal_loss,
        "val/recon_loss": recon_loss
    }
    self.log_dict(loss_metrics, prog_bar=True)
    
    # 第二个字典 (重复键!)
    all_metrics = {
        "val/focal_loss": focal_loss,  # 重复!
        "val/kl_loss": kl_loss
    }
    self.log_dict(all_metrics, sync_dist=True)  # 不同参数
```

#### 模式C: 在 `_step` 方法中多次调用
```python
def _step(self, batch, prefix):
    # ... 计算 ...
    
    # 第一次记录
    self.log_dict({f"{prefix}/focal_loss": focal_loss})
    
    # 在其他地方又记录了
    if prefix == "val":
        self.log("val/focal_loss", focal_loss, on_epoch=True)  # 重复!
```

### 3. **数据分割相关问题**

如果你最近添加了数据分割功能，可能导致：

#### 问题A: 多个验证数据加载器
```python
def val_dataloader(self):
    # 如果返回多个数据加载器
    return [val_loader1, val_loader2]  # 会导致validation_step被多次调用
```

#### 问题B: 交叉验证循环
```python
# 如果在训练循环中有交叉验证
for fold in range(k_folds):
    # 每个fold都可能记录相同的指标
    trainer.fit(model, train_loader, val_loader)
```

### 4. **继承和回调问题**

#### 问题A: 父类中的重复记录
```python
class BaseModel(LightningModule):
    def validation_step(self, batch, batch_idx):
        # 父类记录了指标
        self.log("val/focal_loss", some_loss)

class YourModel(BaseModel):
    def validation_step(self, batch, batch_idx):
        super().validation_step(batch, batch_idx)  # 第一次记录
        # 子类又记录了相同指标
        self.log("val/focal_loss", another_loss)  # 重复!
```

#### 问题B: 自定义回调函数
```python
class CustomCallback(Callback):
    def on_validation_batch_end(self, ...):
        # 回调函数中记录了指标
        pl_module.log("val/focal_loss", some_value)
```

### 5. **多进程/多GPU问题**

在分布式训练中，如果同步设置不当：
```python
# 不一致的sync_dist设置
self.log("val/focal_loss", loss1, sync_dist=True)   # 第一次
self.log("val/focal_loss", loss2, sync_dist=False)  # 第二次，不同参数
```

## 定位问题的步骤

### 步骤1: 搜索所有 `val/focal_loss` 的记录位置
```bash
grep -n "val/focal_loss" /path/to/model.py
```

### 步骤2: 检查 `validation_step` 和 `_step` 方法
查找这些方法中的所有 `self.log` 和 `self.log_dict` 调用

### 步骤3: 检查最近的代码变更
```bash
git diff HEAD~5 -- model.py | grep -A5 -B5 "log"
```

### 步骤4: 检查数据加载器配置
查看 `val_dataloader()` 方法是否返回多个数据加载器

## 解决方案

### 解决方案1: 统一记录位置
```python
def validation_step(self, batch, batch_idx):
    logits, recon_loss, kl_loss = self(batch)
    focal_loss = self.focal_loss_fn(logits, labels)
    
    # 只在一个地方记录所有指标
    metrics = {
        "val/focal_loss": focal_loss,
        "val/recon_loss": recon_loss,
        "val/kl_loss": kl_loss,
    }
    
    # 统一参数设置
    self.log_dict(
        metrics,
        prog_bar=True,
        sync_dist=True,
        on_epoch=True,
        on_step=False
    )
    
    return focal_loss
```

### 解决方案2: 使用条件记录
```python
def _step(self, batch, prefix):
    # ... 计算 ...
    
    # 收集所有指标，但只记录一次
    metrics = {}
    
    if not hasattr(self, '_logged_this_step'):
        self._logged_this_step = set()
    
    metric_key = f"{prefix}/focal_loss"
    if metric_key not in self._logged_this_step:
        metrics[metric_key] = focal_loss
        self._logged_this_step.add(metric_key)
    
    if metrics:
        self.log_dict(metrics, sync_dist=True)
```

### 解决方案3: 重构验证流程
```python
def validation_step(self, batch, batch_idx):
    return self._step(batch, "val")

def _step(self, batch, prefix):
    # 所有计算
    outputs = self(batch)
    losses = self.compute_losses(outputs, batch)
    
    # 只在最后统一记录
    self._log_step_metrics(losses, prefix)
    
    return losses['total_loss']

def _log_step_metrics(self, losses, prefix):
    """统一的指标记录方法"""
    metrics = {f"{prefix}/{k}": v for k, v in losses.items()}
    self.log_dict(metrics, prog_bar=True, sync_dist=True)
```

## 调试技巧

### 1. 添加调试日志
```python
def validation_step(self, batch, batch_idx):
    print(f"Validation step {batch_idx} - logging metrics...")
    # 在每次log调用前打印
    print("About to log focal_loss")
    self.log("val/focal_loss", focal_loss)
```

### 2. 使用断点调试
在可能的重复记录位置设置断点，查看调用堆栈

### 3. 检查Lightning版本
某些版本的Lightning对重复记录更加严格，考虑升级或降级版本

## 预防措施

1. **代码审查**: 确保每个metric键只在一个地方记录
2. **单元测试**: 为validation_step编写测试
3. **统一模式**: 建立项目的logging最佳实践
4. **文档化**: 记录哪些指标在哪里被记录

## 总结

这个错误的根本原因是 PyTorch Lightning 检测到同一个指标键被记录了多次，且使用了不同的参数配置。解决的关键是：

1. 找到所有记录 `val/focal_loss` 的位置
2. 确保只在一个地方记录
3. 使用一致的logging参数
4. 重构代码以避免重复记录

建议使用上面提供的诊断脚本来自动分析你的代码，找出具体的重复记录位置。